c. try {method( );} catch(Exception e) { } catch(NumberException e) { }

...
틀렸습니다

답인 이유: 블로그 참고했습니다

try 블럭 내에서 예외 발생시, catch 블럭에서 이 예외를 처리할 수 있는 것을 순차적으로 찾아 내려갑니다.
** 일치하는 예외가 없을 시, 예외가 처리되지 않습니다.
Exception (예외의 최고)을 선언한 catch 블럭이 마지막 catch 블럭이 아니면, 컴파일 에러가 발생합니다.
